<?xml version='1.0' encoding='UTF-8'?>
<robot xmlns:xacro="http://ros.org/wiki/xacro" name="x500_base">
  <xacro:include filename="macros.xacro"/>
  <xacro:include filename="materials.xacro"/>
  <xacro:include filename="control.xacro"/>
  <xacro:property name="mesh_prefix" value="file://$(find darm)/models"/>
  <link name="base_link">
    <inertial>
      <mass value="2.0"/>
      <inertia ixx="0.02166666666666667" ixy="0.0" ixz="0.0" iyy="0.02166666666666667" iyz="0.0" izz="0.04000000000000001"/>
    </inertial>
    <visual name="base_link_visual">
      <origin xyz="0.0 0.0 0.025" rpy="0.0 0.0 3.141592654"/>
      <geometry>
        <mesh filename="${mesh_prefix}/x500_base/meshes/NXP-HGD-CF.dae" scale="1 1 1"/>
      </geometry>
    </visual>
    <visual name="5010_motor_base_0">
      <origin xyz="0.174 0.174 0.032" rpy="0.0 0.0 -0.45"/>
      <geometry>
        <mesh filename="${mesh_prefix}/x500_base/meshes/5010Base.dae" scale="1 1 1"/>
      </geometry>
    </visual>
    <visual name="5010_motor_base_1">
      <origin xyz="-0.174 0.174 0.032" rpy="0.0 0.0 -0.45"/>
      <geometry>
        <mesh filename="${mesh_prefix}/x500_base/meshes/5010Base.dae" scale="1 1 1"/>
      </geometry>
    </visual>
    <visual name="5010_motor_base_2">
      <origin xyz="0.174 -0.174 0.032" rpy="0.0 0.0 -0.45"/>
      <geometry>
        <mesh filename="${mesh_prefix}/x500_base/meshes/5010Base.dae" scale="1 1 1"/>
      </geometry>
    </visual>
    <visual name="5010_motor_base_3">
      <origin xyz="-0.174 -0.174 0.032" rpy="0.0 0.0 -0.45"/>
      <geometry>
        <mesh filename="${mesh_prefix}/x500_base/meshes/5010Base.dae" scale="1 1 1"/>
      </geometry>
    </visual>
    <collision name="base_link_collision_0">
      <origin xyz="0.0 0.0 0.007" rpy="0.0 0.0 0.0"/>
      <geometry>
        <box size="0.35355339059327373 0.35355339059327373 0.05"/>
      </geometry>
    </collision>
    <collision name="base_link_collision_1">
      <origin xyz="0.0 -0.098 -0.123" rpy="-0.35 0.0 0.0"/>
      <geometry>
        <box size="0.015 0.015 0.21"/>
      </geometry>
    </collision>
    <collision name="base_link_collision_2">
      <origin xyz="0.0 0.098 -0.123" rpy="0.35 0.0 0.0"/>
      <geometry>
        <box size="0.015 0.015 0.21"/>
      </geometry>
    </collision>
    <collision name="base_link_collision_3">
      <origin xyz="0.0 -0.132 -0.2195" rpy="0.0 0.0 0.0"/>
      <geometry>
        <box size="0.25 0.015 0.015"/>
      </geometry>
    </collision>
    <collision name="base_link_collision_4">
      <origin xyz="0.0 0.132 -0.2195" rpy="0.0 0.0 0.0"/>
      <geometry>
        <box size="0.25 0.015 0.015"/>
      </geometry>
    </collision>
  </link>

<!-- rotor links -->
  <link name="rotor_0">
    <inertial>
      <mass value="0.016076923076923075"/>
      <inertia ixx="3.8464910483993325e-07" ixy="0.0" ixz="0.0" iyy="2.6115851691700804e-05" iyz="0.0" izz="2.649858234714004e-05"/>
    </inertial>
    <visual name="rotor_0_visual">
      <origin xyz="-0.022 -0.14638461538461536 -0.016" rpy="0.0 0.0 0.0"/>
      <geometry>
        <mesh filename="${mesh_prefix}/x500_base/meshes/1345_prop_ccw.stl" scale="0.8461538461538461 0.8461538461538461 0.8461538461538461"/>
      </geometry>
    </visual>
    <visual name="rotor_0_visual_motor_bell">
      <origin xyz="0.0 0.0 -0.032" rpy="0.0 0.0 0.0"/>
      <geometry>
        <mesh filename="${mesh_prefix}/x500_base/meshes/5010Bell.dae" scale="1 1 1"/>
      </geometry>
    </visual>
    <collision name="rotor_0_collision">
      <origin xyz="0.0 0.0 0.0" rpy="0.0 0.0 0.0"/>
      <geometry>
        <box size="0.2792307692307692 0.016923076923076923 0.0008461538461538462"/>
      </geometry>
    </collision>
  </link>
  <link name="rotor_1">
    <inertial>
      <mass value="0.016076923076923075"/>
      <inertia ixx="3.8464910483993325e-07" ixy="0.0" ixz="0.0" iyy="2.6115851691700804e-05" iyz="0.0" izz="2.649858234714004e-05"/>
    </inertial>
    <visual name="rotor_1_visual">
      <origin xyz="-0.022 -0.14638461538461536 -0.016" rpy="0.0 0.0 0.0"/>
      <geometry>
        <mesh filename="${mesh_prefix}/x500_base/meshes/1345_prop_ccw.stl" scale="0.8461538461538461 0.8461538461538461 0.8461538461538461"/>
      </geometry>
    </visual>
    <visual name="rotor_1_visual_motor_top">
      <origin xyz="0.0 0.0 -0.032" rpy="0.0 0.0 0.0"/>
      <geometry>
        <mesh filename="${mesh_prefix}/x500_base/meshes/5010Bell.dae" scale="1 1 1"/>
      </geometry>
    </visual>
    <collision name="rotor_1_collision">
      <origin xyz="0.0 0.0 0.0" rpy="0.0 0.0 0.0"/>
      <geometry>
        <box size="0.2792307692307692 0.016923076923076923 0.0008461538461538462"/>
      </geometry>
    </collision>
  </link>
  <link name="rotor_2">
    <inertial>
      <mass value="0.016076923076923075"/>
      <inertia ixx="3.8464910483993325e-07" ixy="0.0" ixz="0.0" iyy="2.6115851691700804e-05" iyz="0.0" izz="2.649858234714004e-05"/>
    </inertial>
    <visual name="rotor_2_visual">
      <origin xyz="-0.022 -0.14638461538461536 -0.016" rpy="0.0 0.0 0.0"/>
      <geometry>
        <mesh filename="${mesh_prefix}/x500_base/meshes/1345_prop_cw.stl" scale="0.8461538461538461 0.8461538461538461 0.8461538461538461"/>
      </geometry>
    </visual>
    <visual name="rotor_2_visual_motor_top">
      <origin xyz="0.0 0.0 -0.032" rpy="0.0 0.0 0.0"/>
      <geometry>
        <mesh filename="${mesh_prefix}/x500_base/meshes/5010Bell.dae" scale="1 1 1"/>
      </geometry>
    </visual>
    <collision name="rotor_2_collision">
      <origin xyz="0.0 0.0 0.0" rpy="0.0 0.0 0.0"/>
      <geometry>
        <box size="0.2792307692307692 0.016923076923076923 0.0008461538461538462"/>
      </geometry>
    </collision>
  </link>
  <link name="rotor_3">
    <inertial>
      <mass value="0.016076923076923075"/>
      <inertia ixx="3.8464910483993325e-07" ixy="0.0" ixz="0.0" iyy="2.6115851691700804e-05" iyz="0.0" izz="2.649858234714004e-05"/>
    </inertial>
    <visual name="rotor_3_visual">
      <origin xyz="-0.022 -0.14638461538461536 -0.016" rpy="0.0 0.0 0.0"/>
      <geometry>
        <mesh filename="${mesh_prefix}/x500_base/meshes/1345_prop_cw.stl" scale="0.8461538461538461 0.8461538461538461 0.8461538461538461"/>
      </geometry>
    </visual>
    <visual name="rotor_3_visual_motor_top">
      <origin xyz="0.0 0.0 -0.032" rpy="0.0 0.0 0.0"/>
      <geometry>
        <mesh filename="${mesh_prefix}/x500_base/meshes/5010Bell.dae" scale="1 1 1"/>
      </geometry>
    </visual>
    <collision name="rotor_3_collision">
      <origin xyz="0.0 0.0 0.0" rpy="0.0 0.0 0.0"/>
      <geometry>
        <box size="0.2792307692307692 0.016923076923076923 0.0008461538461538462"/>
      </geometry>
    </collision>
  </link>

<!-- Rotor joints -->
  <joint name="rotor_0_joint" type="revolute">
    <parent link="base_link"/>
    <child link="rotor_0"/>
    <origin xyz="0.174 0.174 0.06" rpy="0.0 0.0 0.0"/>
    <axis xyz="0 0 1"/>
    <limit lower="-1e+16" upper="1e+16" effort="10.0" velocity="100.0"/>
  </joint>
  <joint name="rotor_1_joint" type="revolute">
    <parent link="base_link"/>
    <child link="rotor_1"/>
    <origin xyz="-0.174 0.174 0.06" rpy="0.0 0.0 0.0"/>
    <axis xyz="0 0 1"/>
    <limit lower="-1e+16" upper="1e+16" effort="10.0" velocity="100.0"/>
  </joint>
  <joint name="rotor_2_joint" type="revolute">
    <parent link="base_link"/>
    <child link="rotor_2"/>
    <origin xyz="0.174 -0.174 0.06" rpy="0.0 0.0 0.0"/>
    <axis xyz="0 0 1"/>
    <limit lower="-1e+16" upper="1e+16" effort="10.0" velocity="100.0"/>
  </joint>
  <joint name="rotor_3_joint" type="revolute">
    <parent link="base_link"/>
    <child link="rotor_3"/>
    <origin xyz="-0.174 -0.174 0.06" rpy="0.0 0.0 0.0"/>
    <axis xyz="0 0 1"/>
    <limit lower="-1e+16" upper="1e+16" effort="10.0" velocity="100.0"/>
  </joint>


<!-- ARM  -->
  <link name="arm_link">
    <visual>
      <geometry>
          <box size="0.03 0.03 0.002"/>
      </geometry>
      <material name="orange"/>
    </visual>
    <collision>
      <geometry>
         <box size="0.03 0.03 0.002"/>
      </geometry>
    </collision>
    <inertial>
        <mass value="0.100"/>
        <origin xyz="0 0 0" rpy="0 0 0"/>
        <xacro:box_inertia m="0.1" x="0.03" y="0.03" z="0.002"/>
    </inertial>
  </link>
  <joint name="arm_base_fixed_joint" type="fixed">
    <parent link="base_link"/>
    <child link="arm_link"/>
    <origin xyz="0 0 0" rpy="${pi} 0 0"/>
  </joint>
  <link name="link1">
      <visual>
          <geometry>
              <cylinder length="0.0666" radius="0.00666"/>
          </geometry>
          <material name="black">
              <color rgba="0.0 0.0 0.0 1"/>
          </material>
      </visual>
      <inertial>
          <mass value="0.1"/>
          <origin xyz="0 0 0" rpy="0 0 0"/>
          <xacro:cylinder_inertia m="0.1" r="0.00666" h="0.0666"/>
      </inertial>
  </link>
    <!-- Joint1: placed at the end of arm_link (z = 0.002/2 = 0.001) -->
  <joint name="joint1" type="revolute">
      <parent link="arm_link"/>
      <child link="link1"/>
      <origin xyz="0 0 0.033" rpy="0 0 0"/>
      <axis xyz="0 0 1"/>
      <limit lower="-3.14" upper="3.14" effort="1" velocity="1"/>
  </joint>

  <xacro:arm_joint_control joint_name="joint1" link_name="link1"/>
  <link name="link_sphere">
      <visual>
          <geometry>
              <sphere radius="0.00666"/>
          </geometry>
          <material name="black">
              <color rgba="0 0 0 1"/>
          </material>
      </visual>
      <inertial>
          <mass value="0.1"/>
          <origin xyz="0 0 0" rpy="0 0 0"/>
          <xacro:sphere_inertia m="0.1" r="0.00666"/>
      </inertial>
  </link>
    <!-- Joint2: placed at the end of link1 (z = 0.0666/2 = 0.0333) -->
  <joint name="joint2" type="revolute">
      <parent link="link1"/>
      <child link="link_sphere"/>
      <origin xyz="0 0 0.0333" rpy="0 0 0"/>
      <axis xyz="1 0 0"/>
      <limit lower="-3.14" upper="3.14" effort="1" velocity="1"/>
  </joint>
  <xacro:arm_joint_control joint_name="joint2" link_name="link_sphere"/>
  <link name="link2">
      <visual>
          <geometry>
              <cylinder length="0.05" radius="0.00433"/>
          </geometry>
          <material name="green">
              <color rgba="0.2 0.8 0.2 1"/>
          </material>
      </visual>
      <inertial>
          <mass value="0.1"/>
          <origin xyz="0 0 0" rpy="0 0 0"/>
          <xacro:cylinder_inertia m="0.1" r="0.00433" h="0.05"/>
      </inertial>
  </link>
    <!-- Joint3: placed at the end of link_sphere (z = 0.00666) -->
  <joint name="joint3" type="fixed">
      <parent link="link_sphere"/>
      <child link="link2"/>
      <origin xyz="0 0 0.025" rpy="0 0 0"/>
  </joint>

<!-- control tags -->
  <ros2_control name="GazeboSimSystem" type="system">
    <hardware>
        <plugin>gz_ros2_control/GazeboSimSystem</plugin>
    </hardware>

    <!-- chose this for effort controller -->

    <!-- <joint name = "joint1">
      <command_interface name = "effort"/>
      <state_interface name = "position"/>
      <state_interface name = "velocity"/>
      <state_interface name = "effort"/>
    </joint>
    <joint name = "joint2">
      <command_interface name = "effort"/>
      <state_interface name = "position"/>
      <state_interface name = "velocity"/>
      <state_interface name = "effort"/>
    </joint> -->

    <!-- this for position controller -->
    
    <joint name = "joint1">
      <command_interface name = "position"/>
      <state_interface name = "position"/>
    </joint>
    <joint name = "joint2">
      <command_interface name = "position"/>
      <state_interface name = "position"/>
    </joint>
  </ros2_control>

</robot>