<sdf version='1.11'>
  <model name='x500_base'>
    <link name='base_link'>
      <inertial>
        <pose>0 0 0 0 0 0</pose>
        <mass>2.1000000000000001</mass>
        <inertia>
          <ixx>0.021674200000000001</ixx>
          <ixy>0</ixy>
          <ixz>0</ixz>
          <iyy>0.021674200000000001</iyy>
          <iyz>9.1440294336335703e-22</iyz>
          <izz>0.040015000000000009</izz>
        </inertia>
      </inertial>
      <collision name='base_link_collision_0_collision'>
        <pose>0 0 0.0070000000000000001 0 0 0</pose>
        <geometry>
          <box>
            <size>0.35355339059327368 0.35355339059327368 0.050000000000000003</size>
          </box>
        </geometry>
      </collision>
      <collision name='base_link_collision_1_collision_1'>
        <pose>0 -0.098000000000000004 -0.123 -0.34999999999999998 0 0</pose>
        <geometry>
          <box>
            <size>0.014999999999999999 0.014999999999999999 0.20999999999999999</size>
          </box>
        </geometry>
      </collision>
      <collision name='base_link_collision_2_collision_2'>
        <pose>0 0.098000000000000004 -0.123 0.34999999999999998 0 0</pose>
        <geometry>
          <box>
            <size>0.014999999999999999 0.014999999999999999 0.20999999999999999</size>
          </box>
        </geometry>
      </collision>
      <collision name='base_link_collision_3_collision_3'>
        <pose>0 -0.13200000000000001 -0.2195 0 0 0</pose>
        <geometry>
          <box>
            <size>0.25 0.014999999999999999 0.014999999999999999</size>
          </box>
        </geometry>
      </collision>
      <collision name='base_link_collision_4_collision_4'>
        <pose>0 0.13200000000000001 -0.2195 0 0 0</pose>
        <geometry>
          <box>
            <size>0.25 0.014999999999999999 0.014999999999999999</size>
          </box>
        </geometry>
      </collision>
      <collision name='base_link_fixed_joint_lump__arm_link_collision_5'>
        <pose>0 0 0 3.1415926535897931 0 0</pose>
        <geometry>
          <box>
            <size>0.029999999999999999 0.029999999999999999 0.002</size>
          </box>
        </geometry>
      </collision>
      <visual name='base_link_visual_visual'>
        <pose>0 0 0.025000000000000001 0 0 -3.141592653179587</pose>
        <geometry>
          <mesh>
            <scale>1 1 1</scale>
            <uri>model://darm/urdf/x500_base/meshes/NXP-HGD-CF.dae</uri>
          </mesh>
        </geometry>
      </visual>
      <visual name='base_link_fixed_joint_lump__5010_motor_base_0_visual_1'>
        <pose>0.17399999999999999 0.17399999999999999 0.032000000000000001 0 0 -0.45000000000000001</pose>
        <geometry>
          <mesh>
            <scale>1 1 1</scale>
            <uri>model://darm/urdf/x500_base/meshes/5010Base.dae</uri>
          </mesh>
        </geometry>
      </visual>
      <visual name='base_link_fixed_joint_lump__5010_motor_base_1_visual_2'>
        <pose>-0.17399999999999999 0.17399999999999999 0.032000000000000001 0 0 -0.45000000000000001</pose>
        <geometry>
          <mesh>
            <scale>1 1 1</scale>
            <uri>model://darm/urdf/x500_base/meshes/5010Base.dae</uri>
          </mesh>
        </geometry>
      </visual>
      <visual name='base_link_fixed_joint_lump__5010_motor_base_2_visual_3'>
        <pose>0.17399999999999999 -0.17399999999999999 0.032000000000000001 0 0 -0.45000000000000001</pose>
        <geometry>
          <mesh>
            <scale>1 1 1</scale>
            <uri>model://darm/urdf/x500_base/meshes/5010Base.dae</uri>
          </mesh>
        </geometry>
      </visual>
      <visual name='base_link_fixed_joint_lump__5010_motor_base_3_visual_4'>
        <pose>-0.17399999999999999 -0.17399999999999999 0.032000000000000001 0 0 -0.45000000000000001</pose>
        <geometry>
          <mesh>
            <scale>1 1 1</scale>
            <uri>model://darm/urdf/x500_base/meshes/5010Base.dae</uri>
          </mesh>
        </geometry>
      </visual>
      <visual name='base_link_fixed_joint_lump__arm_link_visual_5'>
        <pose>0 0 0 3.1415926535897931 0 0</pose>
        <geometry>
          <box>
            <size>0.029999999999999999 0.029999999999999999 0.002</size>
          </box>
        </geometry>
        <material>
          <diffuse>1 0.25 0 1</diffuse>
          <ambient>1 0.25 0 1</ambient>
        </material>
      </visual>
    </link>
    <joint name='joint1' type='revolute'>
      <pose relative_to='base_link'>0 -4.0413344371862659e-18 -0.033000000000000002 3.1415926535897931 0 0</pose>
      <parent>base_link</parent>
      <child>link1</child>
      <axis>
        <xyz>0 0 1</xyz>
        <limit>
          <lower>-3.1400000000000001</lower>
          <upper>3.1400000000000001</upper>
          <effort>1</effort>
          <velocity>1</velocity>
        </limit>
        <dynamics>
          <spring_reference>0</spring_reference>
          <spring_stiffness>0</spring_stiffness>
        </dynamics>
      </axis>
    </joint>
    <link name='link1'>
      <pose relative_to='joint1'>0 0 0 0 0 0</pose>
      <inertial>
        <pose>0 0 0 0 0 0</pose>
        <mass>0.10000000000000001</mass>
        <inertia>
          <ixx>3.8071890000000003e-05</ixx>
          <ixy>0</ixy>
          <ixz>0</ixz>
          <iyy>3.8071890000000003e-05</iyy>
          <iyz>0</iyz>
          <izz>2.2177800000000001e-06</izz>
        </inertia>
      </inertial>
      <visual name='link1_visual'>
        <pose>0 0 0 0 0 0</pose>
        <geometry>
          <cylinder>
            <length>0.066600000000000006</length>
            <radius>0.0066600000000000001</radius>
          </cylinder>
        </geometry>
        <material>
          <diffuse>0 0 0 1</diffuse>
          <ambient>0 0 0 1</ambient>
        </material>
      </visual>
    </link>
    <joint name='joint2' type='revolute'>
      <pose relative_to='link1'>0 0 0.033300000000000003 0 0 0</pose>
      <parent>link1</parent>
      <child>link_sphere</child>
      <axis>
        <xyz>1 0 0</xyz>
        <limit>
          <lower>-3.1400000000000001</lower>
          <upper>3.1400000000000001</upper>
          <effort>1</effort>
          <velocity>1</velocity>
        </limit>
        <dynamics>
          <spring_reference>0</spring_reference>
          <spring_stiffness>0</spring_stiffness>
        </dynamics>
      </axis>
    </joint>
    <link name='link_sphere'>
      <pose relative_to='joint2'>0 0 0 0 0 0</pose>
      <inertial>
        <pose>0 0 0.012500000000000001 0 0 0</pose>
        <mass>0.20000000000000001</mass>
        <inertia>
          <ixx>5.4326279833333339e-05</ixx>
          <ixy>0</ixy>
          <ixz>0</ixz>
          <iyy>5.4326279833333339e-05</iyy>
          <iyz>0</iyz>
          <izz>2.711669e-06</izz>
        </inertia>
      </inertial>
      <visual name='link_sphere_visual'>
        <pose>0 0 0 0 0 0</pose>
        <geometry>
          <sphere>
            <radius>0.0066600000000000001</radius>
          </sphere>
        </geometry>
        <material>
          <diffuse>0 0 0 1</diffuse>
          <ambient>0 0 0 1</ambient>
        </material>
      </visual>
      <visual name='link_sphere_fixed_joint_lump__link2_visual_1'>
        <pose>0 0 0.025000000000000001 0 0 0</pose>
        <geometry>
          <cylinder>
            <length>0.050000000000000003</length>
            <radius>0.0043299999999999996</radius>
          </cylinder>
        </geometry>
        <material>
          <diffuse>0 1 0 1</diffuse>
          <ambient>0 1 0 1</ambient>
        </material>
      </visual>
    </link>
    <joint name='rotor_0_joint' type='revolute'>
      <pose relative_to='base_link'>0.17399999999999999 0.17399999999999999 0.059999999999999998 0 0 0</pose>
      <parent>base_link</parent>
      <child>rotor_0</child>
      <axis>
        <xyz>0 0 1</xyz>
        <limit>
          <lower>-10000000000000000</lower>
          <upper>10000000000000000</upper>
          <effort>10</effort>
          <velocity>100</velocity>
        </limit>
        <dynamics>
          <spring_reference>0</spring_reference>
          <spring_stiffness>0</spring_stiffness>
        </dynamics>
      </axis>
    </joint>
    <link name='rotor_0'>
      <pose relative_to='rotor_0_joint'>0 0 0 0 0 0</pose>
      <inertial>
        <pose>0 0 0 0 0 0</pose>
        <mass>0.016076923076923079</mass>
        <inertia>
          <ixx>3.846491048399332e-07</ixx>
          <ixy>0</ixy>
          <ixz>0</ixz>
          <iyy>2.6115851691700801e-05</iyy>
          <iyz>0</iyz>
          <izz>2.6498582347140039e-05</izz>
        </inertia>
      </inertial>
      <collision name='rotor_0_collision_collision'>
        <pose>0 0 0 0 0 0</pose>
        <geometry>
          <box>
            <size>0.27923076923076923 0.016923076923076919 0.0008461538461538462</size>
          </box>
        </geometry>
      </collision>
      <visual name='rotor_0_visual_visual'>
        <pose>-0.021999999999999999 -0.14638461538461539 -0.016 0 0 0</pose>
        <geometry>
          <mesh>
            <scale>0.84615399999999996 0.84615399999999996 0.84615399999999996</scale>
            <uri>model://darm/urdf/x500_base/meshes/1345_prop_ccw.stl</uri>
          </mesh>
        </geometry>
      </visual>
      <visual name='rotor_0_visual_motor_bell_visual_1'>
        <pose>0 0 -0.032000000000000001 0 0 0</pose>
        <geometry>
          <mesh>
            <scale>1 1 1</scale>
            <uri>model://darm/urdf/x500_base/meshes/5010Bell.dae</uri>
          </mesh>
        </geometry>
      </visual>
    </link>
    <joint name='rotor_1_joint' type='revolute'>
      <pose relative_to='base_link'>-0.17399999999999999 0.17399999999999999 0.059999999999999998 0 0 0</pose>
      <parent>base_link</parent>
      <child>rotor_1</child>
      <axis>
        <xyz>0 0 1</xyz>
        <limit>
          <lower>-10000000000000000</lower>
          <upper>10000000000000000</upper>
          <effort>10</effort>
          <velocity>100</velocity>
        </limit>
        <dynamics>
          <spring_reference>0</spring_reference>
          <spring_stiffness>0</spring_stiffness>
        </dynamics>
      </axis>
    </joint>
    <link name='rotor_1'>
      <pose relative_to='rotor_1_joint'>0 0 0 0 0 0</pose>
      <inertial>
        <pose>0 0 0 0 0 0</pose>
        <mass>0.016076923076923079</mass>
        <inertia>
          <ixx>3.846491048399332e-07</ixx>
          <ixy>0</ixy>
          <ixz>0</ixz>
          <iyy>2.6115851691700801e-05</iyy>
          <iyz>0</iyz>
          <izz>2.6498582347140039e-05</izz>
        </inertia>
      </inertial>
      <collision name='rotor_1_collision_collision'>
        <pose>0 0 0 0 0 0</pose>
        <geometry>
          <box>
            <size>0.27923076923076923 0.016923076923076919 0.0008461538461538462</size>
          </box>
        </geometry>
      </collision>
      <visual name='rotor_1_visual_visual'>
        <pose>-0.021999999999999999 -0.14638461538461539 -0.016 0 0 0</pose>
        <geometry>
          <mesh>
            <scale>0.84615399999999996 0.84615399999999996 0.84615399999999996</scale>
            <uri>model://darm/urdf/x500_base/meshes/1345_prop_ccw.stl</uri>
          </mesh>
        </geometry>
      </visual>
      <visual name='rotor_1_visual_motor_top_visual_1'>
        <pose>0 0 -0.032000000000000001 0 0 0</pose>
        <geometry>
          <mesh>
            <scale>1 1 1</scale>
            <uri>model://darm/urdf/x500_base/meshes/5010Bell.dae</uri>
          </mesh>
        </geometry>
      </visual>
    </link>
    <joint name='rotor_2_joint' type='revolute'>
      <pose relative_to='base_link'>0.17399999999999999 -0.17399999999999999 0.059999999999999998 0 0 0</pose>
      <parent>base_link</parent>
      <child>rotor_2</child>
      <axis>
        <xyz>0 0 1</xyz>
        <limit>
          <lower>-10000000000000000</lower>
          <upper>10000000000000000</upper>
          <effort>10</effort>
          <velocity>100</velocity>
        </limit>
        <dynamics>
          <spring_reference>0</spring_reference>
          <spring_stiffness>0</spring_stiffness>
        </dynamics>
      </axis>
    </joint>
    <link name='rotor_2'>
      <pose relative_to='rotor_2_joint'>0 0 0 0 0 0</pose>
      <inertial>
        <pose>0 0 0 0 0 0</pose>
        <mass>0.016076923076923079</mass>
        <inertia>
          <ixx>3.846491048399332e-07</ixx>
          <ixy>0</ixy>
          <ixz>0</ixz>
          <iyy>2.6115851691700801e-05</iyy>
          <iyz>0</iyz>
          <izz>2.6498582347140039e-05</izz>
        </inertia>
      </inertial>
      <collision name='rotor_2_collision_collision'>
        <pose>0 0 0 0 0 0</pose>
        <geometry>
          <box>
            <size>0.27923076923076923 0.016923076923076919 0.0008461538461538462</size>
          </box>
        </geometry>
      </collision>
      <visual name='rotor_2_visual_visual'>
        <pose>-0.021999999999999999 -0.14638461538461539 -0.016 0 0 0</pose>
        <geometry>
          <mesh>
            <scale>0.84615399999999996 0.84615399999999996 0.84615399999999996</scale>
            <uri>model://darm/urdf/x500_base/meshes/1345_prop_cw.stl</uri>
          </mesh>
        </geometry>
      </visual>
      <visual name='rotor_2_visual_motor_top_visual_1'>
        <pose>0 0 -0.032000000000000001 0 0 0</pose>
        <geometry>
          <mesh>
            <scale>1 1 1</scale>
            <uri>model://darm/urdf/x500_base/meshes/5010Bell.dae</uri>
          </mesh>
        </geometry>
      </visual>
    </link>
    <joint name='rotor_3_joint' type='revolute'>
      <pose relative_to='base_link'>-0.17399999999999999 -0.17399999999999999 0.059999999999999998 0 0 0</pose>
      <parent>base_link</parent>
      <child>rotor_3</child>
      <axis>
        <xyz>0 0 1</xyz>
        <limit>
          <lower>-10000000000000000</lower>
          <upper>10000000000000000</upper>
          <effort>10</effort>
          <velocity>100</velocity>
        </limit>
        <dynamics>
          <spring_reference>0</spring_reference>
          <spring_stiffness>0</spring_stiffness>
        </dynamics>
      </axis>
    </joint>
    <link name='rotor_3'>
      <pose relative_to='rotor_3_joint'>0 0 0 0 0 0</pose>
      <inertial>
        <pose>0 0 0 0 0 0</pose>
        <mass>0.016076923076923079</mass>
        <inertia>
          <ixx>3.846491048399332e-07</ixx>
          <ixy>0</ixy>
          <ixz>0</ixz>
          <iyy>2.6115851691700801e-05</iyy>
          <iyz>0</iyz>
          <izz>2.6498582347140039e-05</izz>
        </inertia>
      </inertial>
      <collision name='rotor_3_collision_collision'>
        <pose>0 0 0 0 0 0</pose>
        <geometry>
          <box>
            <size>0.27923076923076923 0.016923076923076919 0.0008461538461538462</size>
          </box>
        </geometry>
      </collision>
      <visual name='rotor_3_visual_visual'>
        <pose>-0.021999999999999999 -0.14638461538461539 -0.016 0 0 0</pose>
        <geometry>
          <mesh>
            <scale>0.84615399999999996 0.84615399999999996 0.84615399999999996</scale>
            <uri>model://darm/urdf/x500_base/meshes/1345_prop_cw.stl</uri>
          </mesh>
        </geometry>
      </visual>
      <visual name='rotor_3_visual_motor_top_visual_1'>
        <pose>0 0 -0.032000000000000001 0 0 0</pose>
        <geometry>
          <mesh>
            <scale>1 1 1</scale>
            <uri>model://darm/urdf/x500_base/meshes/5010Bell.dae</uri>
          </mesh>
        </geometry>
      </visual>
    </link>
    <frame name='arm_base_fixed_joint' attached_to='base_link'>
      <pose>0 0 0 3.1415926535897931 0 0</pose>
    </frame>
    <frame name='arm_link' attached_to='arm_base_fixed_joint'>
      <pose>0 0 0 0 0 0</pose>
    </frame>
    <frame name='joint3' attached_to='link_sphere'>
      <pose>0 0 0.025000000000000001 0 0 0</pose>
    </frame>
    <frame name='link2' attached_to='joint3'>
      <pose>0 0 0 0 0 0</pose>
    </frame>
  </model>
</sdf>
