<?xml version="1.0" ?>
<!-- =================================================================================== -->
<!-- |    This document was autogenerated by xacro from robot.urdf.xacro               | -->
<!-- |    EDITING THIS FILE BY HAND IS NOT RECOMMENDED                                 | -->
<!-- =================================================================================== -->
<robot name="x500_base">
  <!--................................ INERTIA MATRICES .............................. -->
  <material name="black">
    <color rgba="0.0 0.0 0.0 1.0"/>
  </material>
  <material name="blue">
    <color rgba="0.0 0.0 0.8 1.0"/>
  </material>
  <material name="green">
    <color rgba="0.0 0.8 0.0 1.0"/>
  </material>
  <material name="yellow">
    <color rgba="1.0 1.0 0.0 1.0"/>
  </material>
  <material name="dark_grey">
    <color rgba="0.2 0.2 0.2 1.0"/>
  </material>
  <material name="orange">
    <color rgba="1.0 0.2 0.0 1.0"/>
  </material>
  <material name="brown">
    <color rgba="0.5450980392156862 0.27058823529411763 0.07450980392156863 1.0"/>
  </material>
  <material name="red">
    <color rgba="0.8 0.0 0.0 1.0"/>
  </material>
  <material name="turquoise">
    <color rgba="0.25098039215686274 0.8784313725490196 0.8156862745098039 1.0"/>
  </material>
  <material name="purple">
    <color rgba="0.5019607843137255 0.0 0.5019607843137255 1.0"/>
  </material>
  <material name="white">
    <color rgba="1.0 1.0 1.0 1.0"/>
  </material>
  <material name="aluminium">
    <color rgba="0.5 0.5 0.5 1"/>
  </material>
  <material name="plastic">
    <color rgba="0.1 0.1 0.1 0.7"/>
  </material>
  <!-- Macro to declare ros2_control system -->
  <link name="base_link">
    <inertial>
      <mass value="2.0"/>
      <inertia ixx="0.02166666666666667" ixy="0.0" ixz="0.0" iyy="0.02166666666666667" iyz="0.0" izz="0.04000000000000001"/>
    </inertial>
    <visual name="base_link_visual">
      <origin rpy="0.0 0.0 3.141592654" xyz="0.0 0.0 0.025"/>
      <geometry>
        <mesh filename="package://darm/urdf/x500_base/meshes/NXP-HGD-CF.dae" scale="1 1 1"/>
      </geometry>
    </visual>
    <visual name="5010_motor_base_0">
      <origin rpy="0.0 0.0 -0.45" xyz="0.174 0.174 0.032"/>
      <geometry>
        <mesh filename="package://darm/urdf/x500_base/meshes/5010Base.dae" scale="1 1 1"/>
      </geometry>
    </visual>
    <visual name="5010_motor_base_1">
      <origin rpy="0.0 0.0 -0.45" xyz="-0.174 0.174 0.032"/>
      <geometry>
        <mesh filename="package://darm/urdf/x500_base/meshes/5010Base.dae" scale="1 1 1"/>
      </geometry>
    </visual>
    <visual name="5010_motor_base_2">
      <origin rpy="0.0 0.0 -0.45" xyz="0.174 -0.174 0.032"/>
      <geometry>
        <mesh filename="package://darm/urdf/x500_base/meshes/5010Base.dae" scale="1 1 1"/>
      </geometry>
    </visual>
    <visual name="5010_motor_base_3">
      <origin rpy="0.0 0.0 -0.45" xyz="-0.174 -0.174 0.032"/>
      <geometry>
        <mesh filename="package://darm/urdf/x500_base/meshes/5010Base.dae" scale="1 1 1"/>
      </geometry>
    </visual>
    <collision name="base_link_collision_0">
      <origin rpy="0.0 0.0 0.0" xyz="0.0 0.0 0.007"/>
      <geometry>
        <box size="0.35355339059327373 0.35355339059327373 0.05"/>
      </geometry>
    </collision>
    <collision name="base_link_collision_1">
      <origin rpy="-0.35 0.0 0.0" xyz="0.0 -0.098 -0.123"/>
      <geometry>
        <box size="0.015 0.015 0.21"/>
      </geometry>
    </collision>
    <collision name="base_link_collision_2">
      <origin rpy="0.35 0.0 0.0" xyz="0.0 0.098 -0.123"/>
      <geometry>
        <box size="0.015 0.015 0.21"/>
      </geometry>
    </collision>
    <collision name="base_link_collision_3">
      <origin rpy="0.0 0.0 0.0" xyz="0.0 -0.132 -0.2195"/>
      <geometry>
        <box size="0.25 0.015 0.015"/>
      </geometry>
    </collision>
    <collision name="base_link_collision_4">
      <origin rpy="0.0 0.0 0.0" xyz="0.0 0.132 -0.2195"/>
      <geometry>
        <box size="0.25 0.015 0.015"/>
      </geometry>
    </collision>
  </link>
  <!-- rotor links -->
  <link name="rotor_0">
    <inertial>
      <mass value="0.016076923076923075"/>
      <inertia ixx="3.8464910483993325e-07" ixy="0.0" ixz="0.0" iyy="2.6115851691700804e-05" iyz="0.0" izz="2.649858234714004e-05"/>
    </inertial>
    <visual name="rotor_0_visual">
      <origin rpy="0.0 0.0 0.0" xyz="-0.022 -0.14638461538461536 -0.016"/>
      <geometry>
        <mesh filename="package://darm/urdf/x500_base/meshes/1345_prop_ccw.stl" scale="0.8461538461538461 0.8461538461538461 0.8461538461538461"/>
      </geometry>
    </visual>
    <visual name="rotor_0_visual_motor_bell">
      <origin rpy="0.0 0.0 0.0" xyz="0.0 0.0 -0.032"/>
      <geometry>
        <mesh filename="package://darm/urdf/x500_base/meshes/5010Bell.dae" scale="1 1 1"/>
      </geometry>
    </visual>
    <collision name="rotor_0_collision">
      <origin rpy="0.0 0.0 0.0" xyz="0.0 0.0 0.0"/>
      <geometry>
        <box size="0.2792307692307692 0.016923076923076923 0.0008461538461538462"/>
      </geometry>
    </collision>
  </link>
  <link name="rotor_1">
    <inertial>
      <mass value="0.016076923076923075"/>
      <inertia ixx="3.8464910483993325e-07" ixy="0.0" ixz="0.0" iyy="2.6115851691700804e-05" iyz="0.0" izz="2.649858234714004e-05"/>
    </inertial>
    <visual name="rotor_1_visual">
      <origin rpy="0.0 0.0 0.0" xyz="-0.022 -0.14638461538461536 -0.016"/>
      <geometry>
        <mesh filename="package://darm/urdf/x500_base/meshes/1345_prop_ccw.stl" scale="0.8461538461538461 0.8461538461538461 0.8461538461538461"/>
      </geometry>
    </visual>
    <visual name="rotor_1_visual_motor_top">
      <origin rpy="0.0 0.0 0.0" xyz="0.0 0.0 -0.032"/>
      <geometry>
        <mesh filename="package://darm/urdf/x500_base/meshes/5010Bell.dae" scale="1 1 1"/>
      </geometry>
    </visual>
    <collision name="rotor_1_collision">
      <origin rpy="0.0 0.0 0.0" xyz="0.0 0.0 0.0"/>
      <geometry>
        <box size="0.2792307692307692 0.016923076923076923 0.0008461538461538462"/>
      </geometry>
    </collision>
  </link>
  <link name="rotor_2">
    <inertial>
      <mass value="0.016076923076923075"/>
      <inertia ixx="3.8464910483993325e-07" ixy="0.0" ixz="0.0" iyy="2.6115851691700804e-05" iyz="0.0" izz="2.649858234714004e-05"/>
    </inertial>
    <visual name="rotor_2_visual">
      <origin rpy="0.0 0.0 0.0" xyz="-0.022 -0.14638461538461536 -0.016"/>
      <geometry>
        <mesh filename="package://darm/urdf/x500_base/meshes/1345_prop_cw.stl" scale="0.8461538461538461 0.8461538461538461 0.8461538461538461"/>
      </geometry>
    </visual>
    <visual name="rotor_2_visual_motor_top">
      <origin rpy="0.0 0.0 0.0" xyz="0.0 0.0 -0.032"/>
      <geometry>
        <mesh filename="package://darm/urdf/x500_base/meshes/5010Bell.dae" scale="1 1 1"/>
      </geometry>
    </visual>
    <collision name="rotor_2_collision">
      <origin rpy="0.0 0.0 0.0" xyz="0.0 0.0 0.0"/>
      <geometry>
        <box size="0.2792307692307692 0.016923076923076923 0.0008461538461538462"/>
      </geometry>
    </collision>
  </link>
  <link name="rotor_3">
    <inertial>
      <mass value="0.016076923076923075"/>
      <inertia ixx="3.8464910483993325e-07" ixy="0.0" ixz="0.0" iyy="2.6115851691700804e-05" iyz="0.0" izz="2.649858234714004e-05"/>
    </inertial>
    <visual name="rotor_3_visual">
      <origin rpy="0.0 0.0 0.0" xyz="-0.022 -0.14638461538461536 -0.016"/>
      <geometry>
        <mesh filename="package://darm/urdf/x500_base/meshes/1345_prop_cw.stl" scale="0.8461538461538461 0.8461538461538461 0.8461538461538461"/>
      </geometry>
    </visual>
    <visual name="rotor_3_visual_motor_top">
      <origin rpy="0.0 0.0 0.0" xyz="0.0 0.0 -0.032"/>
      <geometry>
        <mesh filename="package://darm/urdf/x500_base/meshes/5010Bell.dae" scale="1 1 1"/>
      </geometry>
    </visual>
    <collision name="rotor_3_collision">
      <origin rpy="0.0 0.0 0.0" xyz="0.0 0.0 0.0"/>
      <geometry>
        <box size="0.2792307692307692 0.016923076923076923 0.0008461538461538462"/>
      </geometry>
    </collision>
  </link>
  <!-- Rotor joints -->
  <joint name="rotor_0_joint" type="revolute">
    <parent link="base_link"/>
    <child link="rotor_0"/>
    <origin rpy="0.0 0.0 0.0" xyz="0.174 0.174 0.06"/>
    <axis xyz="0 0 1"/>
    <limit effort="10.0" lower="-1e+16" upper="1e+16" velocity="100.0"/>
  </joint>
  <joint name="rotor_1_joint" type="revolute">
    <parent link="base_link"/>
    <child link="rotor_1"/>
    <origin rpy="0.0 0.0 0.0" xyz="-0.174 0.174 0.06"/>
    <axis xyz="0 0 1"/>
    <limit effort="10.0" lower="-1e+16" upper="1e+16" velocity="100.0"/>
  </joint>
  <joint name="rotor_2_joint" type="revolute">
    <parent link="base_link"/>
    <child link="rotor_2"/>
    <origin rpy="0.0 0.0 0.0" xyz="0.174 -0.174 0.06"/>
    <axis xyz="0 0 1"/>
    <limit effort="10.0" lower="-1e+16" upper="1e+16" velocity="100.0"/>
  </joint>
  <joint name="rotor_3_joint" type="revolute">
    <parent link="base_link"/>
    <child link="rotor_3"/>
    <origin rpy="0.0 0.0 0.0" xyz="-0.174 -0.174 0.06"/>
    <axis xyz="0 0 1"/>
    <limit effort="10.0" lower="-1e+16" upper="1e+16" velocity="100.0"/>
  </joint>
  <!-- ARM  -->
  <link name="arm_link">
    <visual>
      <geometry>
        <box size="0.03 0.03 0.002"/>
      </geometry>
      <material name="orange"/>
    </visual>
    <collision>
      <geometry>
        <box size="0.03 0.03 0.002"/>
      </geometry>
    </collision>
    <inertial>
      <mass value="0.100"/>
      <origin rpy="0 0 0" xyz="0 0 0"/>
      <inertia ixx="7.533333333333334e-06" ixy="0" ixz="0" iyy="7.533333333333334e-06" iyz="0" izz="1.5e-05"/>
    </inertial>
  </link>
  <joint name="arm_base_fixed_joint" type="fixed">
    <parent link="base_link"/>
    <child link="arm_link"/>
    <origin rpy="3.141592653589793 0 0" xyz="0 0 0"/>
  </joint>
  <link name="link1">
    <visual>
      <geometry>
        <cylinder length="0.0666" radius="0.00666"/>
      </geometry>
      <material name="black">
        <color rgba="0.0 0.0 0.0 1"/>
      </material>
    </visual>
    <inertial>
      <mass value="0.1"/>
      <origin rpy="0 0 0" xyz="0 0 0"/>
      <inertia ixx="3.807189e-05" ixy="0" ixz="0" iyy="3.807189e-05" iyz="0" izz="2.21778e-06"/>
    </inertial>
  </link>
  <!-- Joint1: placed at the end of arm_link (z = 0.002/2 = 0.001) -->
  <joint name="joint1" type="revolute">
    <parent link="arm_link"/>
    <child link="link1"/>
    <origin rpy="0 0 0" xyz="0 0 0.033"/>
    <axis xyz="0 0 1"/>
    <limit effort="1" lower="-3.14" upper="3.14" velocity="1"/>
  </joint>
  <link name="link_sphere">
    <visual>
      <geometry>
        <sphere radius="0.00666"/>
      </geometry>
      <material name="black">
        <color rgba="0 0 0 1"/>
      </material>
    </visual>
    <inertial>
      <mass value="0.1"/>
      <origin rpy="0 0 0" xyz="0 0 0"/>
      <inertia ixx="1.7742240000000001e-06" ixy="0" ixz="0" iyy="1.7742240000000001e-06" iyz="0" izz="1.7742240000000001e-06"/>
    </inertial>
  </link>
  <!-- Joint2: placed at the end of link1 (z = 0.0666/2 = 0.0333) -->
  <joint name="joint2" type="revolute">
    <parent link="link1"/>
    <child link="link_sphere"/>
    <origin rpy="0 0 0" xyz="0 0 0.0333"/>
    <axis xyz="1 0 0"/>
    <limit effort="1" lower="-3.14" upper="3.14" velocity="1"/>
  </joint>
  <link name="link2">
    <visual>
      <geometry>
        <cylinder length="0.05" radius="0.00433"/>
      </geometry>
      <material name="green">
        <color rgba="0.2 0.8 0.2 1"/>
      </material>
    </visual>
    <inertial>
      <mass value="0.1"/>
      <origin rpy="0 0 0" xyz="0 0 0"/>
      <inertia ixx="2.130205583333334e-05" ixy="0" ixz="0" iyy="2.130205583333334e-05" iyz="0" izz="9.37445e-07"/>
    </inertial>
  </link>
  <!-- Joint3: placed at the end of link_sphere (z = 0.00666) -->
  <joint name="joint3" type="fixed">
    <parent link="link_sphere"/>
    <child link="link2"/>
    <origin rpy="0 0 0" xyz="0 0 0.025"/>
  </joint>
  <!-- control tags -->
  <ros2_control name="GazeboSimSystem" type="system">
    <hardware>
      <plugin>gz_ros2_control/GazeboSimSystem</plugin>
    </hardware>
    <ros2_control_block joint_names="joint1"/>
    <ros2_control_block joint_names="joint2"/>
  </ros2_control>
  <!--................................ INERTIA MATRICES .............................. -->
  <!-- Macro to declare ros2_control system -->
  <plugin filename="gz_ros2_control-system" name="gz_ros2_control::GazeboSimROS2ControlPlugin">
    <robot_param>robot_description</robot_param>
    <robot_param_node>robot_state_publisher</robot_param_node>
    <parameters>package://darm/config/arm_control.yaml</parameters>
  </plugin>
</robot>
